<?xml version="1.0" ?>

<robot name="basic_amr">
  
  <material name="white">
    <color rgba="1 1 1 1"/>
  </material>

  <material name="black">
    <color rgba="0 0 0 1"/>
  </material>

  <material name="green">
    <color rgba="0.1 0.8 0.1 1"/>
  </material>

  <!-- Begin - Robot description -->

  <link name="base_link" />

  <joint name="base__base_link" type="fixed">
    <parent link="base_link"/>
    <child link="base"/>
  </joint>

  <link name="base">
    <origin rpy="0 0 0" xyz="0.00 0 0.00"/>
    <visual>
      <geometry>
        <box size="1.0 0.5 0.6"/>
      </geometry>
      <material name="green"/>
    </visual>
  </link>

  <link name="fcastor_wheel">
    <origin rpy="0 0 0" xyz="0.00 0 0.00"/>
    <visual>
      <geometry>
        <cylinder length="0.1" radius="0.05"/>
      </geometry>
      <material name="black"/>
    </visual>
  </link>
  
  <joint name="base__fcastor_wheel" type="continuous">
    <parent link="base"/>
    <child link="fcastor_wheel"/>
    <origin xyz="0.4 0 -0.35" rpy="1.5708 0 0"/>
    <axis xyz="0 0 1"/>
  </joint>

  <link name="bcastor_wheel">
    <origin rpy="0 0 0" xyz="0.00 0 0.00"/>
    <visual>
      <geometry>
        <cylinder length="0.1" radius="0.05"/>
      </geometry>
      <material name="black"/>
    </visual>
  </link>
  
  <joint name="base__bcastor_wheel" type="continuous">
    <parent link="base"/>
    <child link="bcastor_wheel"/>
    <origin xyz="-0.4 0 -0.35" rpy="1.5708 0 0"/>
    <axis xyz="0 0 1"/>
  </joint>

  <link name="left_wheel">
    <origin rpy="0 0 0" xyz="0.00 0 0.00"/>
    <visual>
      <geometry>
        <cylinder length="0.2" radius="0.4"/>
      </geometry>
      <material name="black"/>
    </visual>
  </link>
  
  <joint name="wheel_left_joint" type="continuous">
    <parent link="base"/>
    <child link="left_wheel"/>
    <origin xyz="0 0.4 0.0" rpy="1.5708 0 0"/>
    <axis xyz="0 0 -1"/>
  </joint>

  <link name="right_wheel">
    <origin rpy="0 0 0" xyz="0.00 0 0.00"/>
    <visual>
      <geometry>
        <cylinder length="0.2" radius="0.4"/>
      </geometry>
      <material name="black"/>
    </visual>
  </link>
  
  <joint name="wheel_right_joint" type="continuous">
    <parent link="base"/>
    <child link="right_wheel"/>
    <origin xyz="0 -0.4 0.0" rpy="1.5708 0 0"/>
    <axis xyz="0 0 -1"/>
  </joint>

  <!-- End - Robot description -->

</robot>